---
title: 事务
categories: 
- Spring技术内幕
---

# 事务失效

**@Transactional应用在非 public 修饰的方法上**

* 如果`Transactional`注解应用在非`public` 修饰的方法上，Transactional将会失效

* 注意：protected、private 修饰的方法上使用 @Transactional 注解，虽然事务无效，但不会有任何报错 

**@Transactional注解属性 rollbackFor设置错误**

`rollbackFor` 可以指定能够触发事务回滚的异常类型

* Spring默认抛出了未检查`unchecked`异常（继承自 `RuntimeException` 的异常）或者 `Error`才回滚事务；其他异常不会触发回滚事务

如果在事务中抛出其他类型的异常，但却期望 Spring 能够回滚事务，就需要指定 **rollbackFor**属性

* 若在目标方法中抛出的异常是 `rollbackFor` 指定的异常的子类，事务同样会回滚

**同一个类中方法调用，导致@Transactional失效**

开发中避免不了会对同一个类里面的方法调用，比如有一个类Test，它的一个方法A，A再调用本类的方法B（不论方法B是用public还是private修饰），但方法A没有声明注解事务，而B方法有，则外部调用方法A之后，方法B的事务是不会起作用的。

* 由于使用`Spring AOP`代理造成的，因为只有当事务方法被当前类以外的代码调用时，才会由`Spring`生成的代理对象来管理

**异常被你的catch导致@Transactional失效**

```java
    @Transactional
    private Integer A() throws Exception {
        int insert = 0;
        try {
            CityInfoDict cityInfoDict = new CityInfoDict();
            cityInfoDict.setCityName("2");
            cityInfoDict.setParentCityId(2);
            /**
             * A 插入字段为 2的数据
             */
            insert = cityInfoDictMapper.insert(cityInfoDict);
            /**
             * B 插入字段为 3的数据
             */
            b.insertB();
        } catch (Exception e) {
            e.printStackTrace();
        }
    }
```

如果B方法内部抛了异常，而A方法此时try catch了B方法的异常，那这个事务不能正常回滚

会抛出异常：

```plain
org.springframework.transaction.UnexpectedRollbackException: Transaction rolled back because it has been marked as rollback-only
```

`spring`的事务是在调用业务方法之前开始的，业务方法执行完毕之后才执行`commit` or `rollback`，事务是否执行取决于是否抛出`runtime异常`，如果抛出`runtime exception` 并在你的业务方法中没有catch到的话，事务会回滚

在业务方法中一般不需要catch异常，如果非要catch一定要抛出`throw new RuntimeException()`